Workbook
Name ACTION: #REF!

Sheet Guideline
A1: Guideline to make and understand Unit Test Case
A3: 1. Overview
A4: - In the template, Unit test cases are based on functions. Each sheet presents test cases for one function.
A5: - Cover: General information of the project and Unit Test cases
A6: - FunctionList: The list of Classes and Functions in the document. + To control that the number of Unit TC meets customer's requirement or the norm, user should fill value for 'Normal number of Test cases/KLOC'.
A7: + Click on Function link to open the related Test cases of the function. Note: You should create new Function sheet before creating the link
A8: - Test Report: provive the overview results of Functions Unit test: Test coverage, Test successful coverage (Summary, for normal/abnormal/boundary cases)
A9: Note: Should check the formula of "Sub Total" if you add more functions
A11: 2. Content in Test function sheet
A12: 2.1 Combination of test cases.
A13: - To verify that number of Unit TC meets customer's requirement or not. User has to fill number LOC of tested function and fill value of 'Normal number test cases/KLOC' item in FunctionList sheet, which is required by customer or normal value. The number of lacked TC is shown in 'Lack of test cases' item.
A14: - If the number of Unit TC does not meet the requirement, creator should explain the reasons.
... A47: - Test requirement: Brief description about requirements which are tested in this function, it is not mandatory.

Sheet Cover
B2: UNIT TEST DOCUMENT
A4: Project Name | B4: PharmacyLife Website | E4: Creator | F4: hao, kien
A5: Project Code | B5: PLW | E5: Issue Date | F5: 46103
A6: Document Code | B6: =B5&"_"&"Unit Test Document"&"_"&"v1.0" -> PLW_Unit Test Document_v1.0 | E6: Version | F6: 1
A9: Record of change
A10: Effective Date | B10: Version | C10: Change Item | D10: *A,D,M | E10: Change description | F10: Reference
A11: 46103 | B11: 1.0 | C11: A | E11: First version of Unit Test Document for PharmacyLife Website. | F11: Guideline

Sheet Functions
E2: Function List
A4: Project Name | E4: =Cover!B4 -> PharmacyLife Website
A5: Project Code | E5: =Cover!B5 -> PLW
A6: Normal number of Test cases/KLOC | E6: 90
A7: Test Environment Setup Description | E7: <List enviroment requires in this system 1. Server : Localhost 2. Database : SQL Server 3. Web Browser : Google Chrome, Microsoft Edge 4. Tools: Visual Studio >
A10: No | B10: Requirement Name | C10: Class Name | D10: Function Name | E10: Function Code(Optional) | F10: Sheet Name | G10: Description | H10: Pre-Condition
A11: 1 | B11: Unit Conversion | C11: Medicine | D11: getDisplayQuantity | F11: getDisplayQuantity | G11: Displays the quantity of products in the appropriate unit, with conversion support if a base unit is available. | H11: app running
A12: 2 | B12: Data Mapping | C12: Medicine | D12: setCategoryID | F12: setCategoryID | G12: This function is used to receive a string in CategoryID format and convert it into an integer for the CategoryId attribute in the model. | H12: app running
A13: 3 | B13: Price Retrieval | C13: Medicine | D13: getSellingPrice | F13: getSellingPrice | G13: Returns the selling price from baseUnit when baseUnit is available. | H13: app running
A14: 4 | B14: Cart Calculation | C14: Cart | D14: getTotalMoney | F14: getTotalMoney | G14: Used to calculate the total price of the shopping cart/product list. | H14: app running
A15: 5 | B15: Medicine Calculation | C15: Cart | D15: getTotalPrice | F15: getTotalPrice | G15: Used to calculate the total price for each medicine in the system. | H15: app running
A16: 6 | B16: Order | C16: Order item | D16: getTotalPrice (Order) | F16: getTotalPrice (Order) | G16: Perform authentication and handle various input conditions. | H16: app running
A17: 7 | B17: Total Amount | C17: Import | D17: recalculateTotal | F17: recalculateTotal | G17: The function calculate totalAmount as quantity × unitPrice | H17: app running
A18: 8 | B18: Update Quantity | C18: Cart | D18: updateQuantity | F18: updateQuantity | G18: Updates the quantity of an item in the cart | H18: app running
A19: 9 | B19: Item Count | C19: Cart | D19: getitemCount | F19: getitemCount | G19: Calculates the total quantity of all items in the list | H19: app running

Sheet Statistics
A2: UNIT TEST REPORT
A4: Project Name | B4: =Cover!B4 -> PharmacyLife Website | D4: Creator | F4: hao, kien
A5: Project Code | B5: =Cover!B5 -> PLW | D5: Reviewer/Approver | F5: LanLT11
A6: Document Code | B6: =B5&"_"&"Unit Test Report"&"_"&"v1.0" -> PLW_Unit Test Report_v1.0 | D6: Issue Date | F6: 46103
A7: Notes
A11: No | B11: Function code | C11: Passed | D11: Failed | E11: Untested | F11: N | G11: A | H11: B | I11: Total Test Cases
A12: 1 | B12: getDisplayQuantity | C12: =getDisplayQuantity!A7 -> 14 | D12: =getDisplayQuantity!C7 -> 0 | E12: =getDisplayQuantity!F7 -> 1 | F12: =getDisplayQuantity!L7 -> 4 | G12: =getDisplayQuantity!M7 -> 4 | H12: =getDisplayQuantity!N7 -> 6 | I12: =getDisplayQuantity!O7 -> 15
A13: 2 | B13: setCategoryID | C13: =' setCategoryID'!A7 -> 10 | D13: =' setCategoryID'!C7 -> 0 | E13: =' setCategoryID'!F7 -> 5 | F13: =' setCategoryID'!L7 -> 1 | G13: =' setCategoryID'!M7 -> 6 | H13: =' setCategoryID'!N7 -> 3 | I13: =' setCategoryID'!O7 -> 15
A14: 3 | B14: getSellingPrice | C14: =getSellingPrice!A7 -> 6 | D14: =getSellingPrice!C7 -> 0 | E14: =getSellingPrice!F7 -> 9 | F14: =getSellingPrice!L7 -> 3 | G14: =getSellingPrice!M7 -> 5 | H14: =getSellingPrice!N7 -> 2 | I14: =getSellingPrice!O7 -> 15
A15: 4 | B15: getTotalMoney | C15: =getTotalMoney!A7 -> 10 | D15: =getTotalMoney!C7 -> 0 | E15: =getTotalMoney!F7 -> 5 | F15: =getTotalMoney!L7 -> 4 | G15: =getTotalMoney!M7 -> 3 | H15: =getTotalMoney!N7 -> 3 | I15: =getTotalMoney!O7 -> 15
A16: 5 | B16: getTotalPrice | C16: =getTotalPrice!A7 -> 10 | D16: =getTotalPrice!C7 -> 0 | E16: =getTotalPrice!F7 -> 5 | F16: =getTotalPrice!L7 -> 4 | G16: =getTotalPrice!M7 -> 2 | H16: =getTotalPrice!N7 -> 4 | I16: =getTotalPrice!O7 -> 15
A17: 6 | B17: getTotalPrice(Order) | C17: ='getTotalPrice(Order)'!A7 -> 9 | D17: ='getTotalPrice(Order)'!C7 -> 0 | E17: ='getTotalPrice(Order)'!F7 -> 6 | F17: ='getTotalPrice(Order)'!L7 -> 3 | G17: ='getTotalPrice(Order)'!M7 -> 3 | H17: ='getTotalPrice(Order)'!N7 -> 3 | I17: ='getTotalPrice(Order)'!O7 -> 15
A18: 7 | B18: recalculateTotal | C18: =recalculateTotal!A7 -> 14 | D18: =recalculateTotal!C7 -> 0 | E18: =recalculateTotal!F7 -> 1 | F18: =recalculateTotal!L7 -> 5 | G18: =recalculateTotal!M7 -> 5 | H18: =recalculateTotal!N7 -> 4 | I18: =recalculateTotal!O7 -> 15
A19: 8 | B19: updateQuantity | C19: =updateQuantity!A7 -> 15 | D19: =updateQuantity!C7 -> 0 | E19: =updateQuantity!F7 -> 0 | F19: =updateQuantity!L7 -> 6 | G19: =updateQuantity!M7 -> 5 | H19: =updateQuantity!N7 -> 4 | I19: =updateQuantity!O7 -> 15
A20: 9 | B20: getitemCount | C20: =getItemCount!A7 -> 15 | D20: =getItemCount!C7 -> 0 | E20: =getItemCount!F7 -> 0 | F20: =getItemCount!L7 -> 5 | G20: =getItemCount!M7 -> 7 | H20: =getItemCount!N7 -> 3 | I20: =getItemCount!O7 -> 15
B21: Sub total | C21: =SUM(C10:C17) -> 59 | D21: =SUM(D10:D17) -> 0 | E21: =SUM(E10:E17) -> 31 | F21: =SUM(F10:F17) -> 19 | G21: =SUM(G10:G17) -> 23 | H21: =SUM(H10:H17) -> 21 | I21: =SUM(I10:I17) -> 90
B23: Test coverage | D23: =(C21+D21)*100/(I21) -> 65.555556 | E23: %
B24: Test successful coverage | D24: =C21*100/(I21) -> 65.555556 | E24: %
B25: Normal case | D25: =F21*100/I21 -> 21.111111 | E25: %
B26: Abnormal case | D26: =G21*100/I21 -> 25.555556 | E26: %
B27: Boundary case | D27: =H21*100/I21 -> 23.333333 | E27: %

Sheet getDisplayQuantity
A2: Function Code | C2: getDisplayQuantity | F2: Function Name | L2: getDisplayQuantity
A3: Created By | C3: Kien | F3: Executed By | L3: Kien
A4: Lines of code | C4: 5 | F4: Lack of test cases | L4: =IF(Functions!E6<>"N/A",SUM(C4*Functions!E6/1000,- O7),"N/A") -> -14.55
A5: Test requirement | C5: Displays the quantity of products in the appropriate unit, with conversion support if a base unit is available.
A6: Passed | C6: Failed | F6: Untested | L6: N/A/B | O6: Total Test Cases
A7: =COUNTIF(F57:HV57,"P") -> 14 | C7: =COUNTIF(F57:HV57,"F") -> 0 | F7: =SUM(O7,- A7,- C7) -> 1 | L7: =COUNTIF(E56:HV56,"N") -> 4 | M7: =COUNTIF(E56:HV56,"A") -> 4 | N7: =COUNTIF(E56:HV56,"B") -> 6 | O7: =COUNTA(E9:HY9) -> 15
F9: UTCID01 | G9: UTCID02 | H9: UTCID03 | I9: UTCID04 | J9: UTCID05 | K9: UTCID06 | L9: UTCID07 | M9: UTCID08 | N9: UTCID09 | O9: UTCID10 | P9: UTCID11 | Q9: UTCID12 | R9: UTCID13 | S9: UTCID14 | T9: UTCID15
A10: Condition | B10: Precondition | D10: app running
B14: remainingQuantity
D15: -100 | L15: O
D16: 50 | M16: O
D17: 99 | N17: O
D18: 100 | F18: O | G18: O | H18: O | J18: O | K18: O | O18: O
D19: 0 | I19: O | P19: O
D20: 1 | Q20: O
D21: 95 | S21: O
D22: 1000000 | R22: O
B23: conversionRate
D24: -10 | K24: O | L24: O
D25: 0 | H25: O
D26: 1 | J26: O | O26: O | Q26: O
D27: 5 | M27: O
D28: 10 | F28: O | I28: O | N28: O | P28: O | S28: O
D29: 100 | R29: O
D30: null | G30: O
A42: Confirm | B42: Return | D42: 100 | G42: O | H42: O | J42: O | K42: O | O42: O
D43: -10 | L43: O
D44: 0 | I44: O | P44: O
D45: 1 | Q45: O
D46: 9 | N46: O | S46: O
D47: 10 | F47: O | M47: O
D48: 10000 | R48: O
B51: Exception
B53: Log message
A56: Result | B56: Type(N : Normal, A : Abnormal, B : Boundary) | F56: N | G56: A | H56: A | I56: B | J56: B | K56: A | L56: A | M56: N | N56: B | O56: N | P56: B | Q56: B | R56: N | S56: B
B57: Passed/Failed | F57: P | G57: P | H57: P | I57: P | J57: P | K57: P | L57: P | M57: P | N57: P | O57: P | P57: P | Q57: P | R57: P | S57: P
B58: Executed Date | F58: 46103 | G58: 46103 | H58: 46103 | I58: 46103 | J58: 46103 | K58: 46103 | L58: 46103 | M58: 46103 | N58: 46103 | O58: 46103 | P58: 46103 | Q58: 46103 | R58: 46103 | S58: 46103
B59: Defect ID

Sheet  setCategoryID
A2: Function Code | C2: setCategoryID | F2: Function Name | L2: setCategoryID
A3: Created By | C3: Kien | F3: Executed By
A4: Lines of code | C4: 7 | F4: Lack of test cases | L4: =IF(Functions!E6<>"N/A",SUM(C4*Functions!E6/1000,- O7),"N/A") -> -14.37
A5: Test requirement | C5: This function is used to receive a string in CategoryID format and convert it into an integer for the CategoryId attribute in the model.
A6: Passed | C6: Failed | F6: Untested | L6: N/A/B | O6: Total Test Cases
A7: =COUNTIF(F42:HQ42,"P") -> 10 | C7: =COUNTIF(F42:HQ42,"F") -> 0 | F7: =SUM(O7,- A7,- C7) -> 5 | L7: =COUNTIF(E41:HQ41,"N") -> 1 | M7: =COUNTIF(E41:HQ41,"A") -> 6 | N7: =COUNTIF(E41:HQ41,"B") -> 3 | O7: =COUNTA(E9:HT9) -> 15
F9: UTCID01 | G9: UTCID02 | H9: UTCID03 | I9: UTCID04 | J9: UTCID05 | K9: UTCID06 | L9: UTCID07 | M9: UTCID08 | N9: UTCID09 | O9: UTCID10 | P9: UTCID11 | Q9: UTCID12 | R9: UTCID13 | S9: UTCID14 | T9: UTCID15
A10: Condition | B10: Precondition | D10: app running
B14: categoryID input
D15: "-1" | F15: O
D16: "" | G16: O
D17: null | H17: O
D18: "5" | I18: O
D19: "10" | J19: O
D20: "abc" | K20: O
D21: 10.5 | L21: O
D22: 0 | M22: O
D23: "10 abc" | N23: O
D24: "00005"
A31: Confirm | B31: Return | D31: -1 | F31: O | H31: O | K31: O | L31: O | N31: O
D32: 0 | G32: O | K32: O | M32: O
D33: 5 | I33: O
D34: 10 | J34: O
D35: 5 | O35: O
B36: Exception
B38: Log message
A41: Result | B41: Type(N : Normal, A : Abnormal, B : Boundary) | F41: A | G41: A | H41: A | I41: B | J41: B | K41: A | L41: A | M41: B | N41: A | O41: N
B42: Passed/Failed | F42: P | G42: P | H42: P | I42: P | J42: P | K42: P | L42: P | M42: P | N42: P | O42: P
B43: Executed Date | F43: 46103 | G43: 46103 | H43: 46103 | I43: 46103 | J43: 46103 | K43: 46103 | L43: 46103 | M43: 46103 | N43: 46103 | O43: 46103
B44: Defect ID

Sheet getSellingPrice
A2: Function Code | C2: getSellingPrice | F2: Function Name | L2: getSellingPrice
A3: Created By | C3: Kien | F3: Executed By | L3: Kien
A4: Lines of code | C4: 6 | F4: Lack of test cases | L4: =IF(Functions!E6<>"N/A",SUM(C4*Functions!E6/1000,- O7),"N/A") -> -14.46
A5: Test requirement | C5: Returns the selling price from baseUnit when baseUnit is available. If baseUnit is null, it falls back to the legacy sellingPrice field.
A6: Passed | C6: Failed | F6: Untested | L6: N/A/B | O6: Total Test Cases
A7: =COUNTIF(F42:K42,"P") -> 6 | C7: =COUNTIF(F42:HQ42,"F") -> 0 | F7: =SUM(O7,- A7,- C7) -> 9 | L7: =COUNTIF(E41:HQ41,"N") -> 3 | M7: =COUNTIF(E41:HQ41,"A") -> 5 | N7: =COUNTIF(E41:HQ41,"B") -> 2 | O7: =COUNTA(E9:HT9) -> 15
F9: UTCID01 | G9: UTCID02 | H9: UTCID03 | I9: UTCID04 | J9: UTCID05 | K9: UTCID06 | L9: UTCID07 | M9: UTCID08 | N9: UTCID09 | O9: UTCID10 | P9: UTCID11 | Q9: UTCID12 | R9: UTCID13 | S9: UTCID14 | T9: UTCID15
A10: Condition | B10: Precondition | D10: app running
B14: baseUnit
D15: not null | F15: O | H15: O | J15: O | L15: O | M15: O | N15: O | O15: O
D16: null | G16: O | I16: O | K16: O
B18: baseUnit.sellingPrice
D19: 12000.5 | F19: O | G19: O | I19: O | K19: O | L19: O | N19: O
D20: 0 | H20: O
D21: -1 | J21: O
D22: "abc" | M22: O
D23: null | O23: O
B25: sellingPrice
D26: 15000 | F26: O | G26: O | H26: O | J26: O | M26: O | O26: O
D27: 0 | I27: O
D28: -1 | K28: O
D29: 12000.5 | L29: O
D30: "xyz" | N30: O
A33: Confirm | B33: Return | D33: -1 | J33: O | K33: O | M33: O
D34: 12000.5 | F34: O | L34: O
D35: 15000 | G35: O
B36: Exception | D36: 0 | H36: O | I36: O
B38: Log message
A41: Result | B41: Type(N : Normal, A : Abnormal, B : Boundary) | F41: N | G41: N | H41: B | I41: B | J41: A | K41: A | L41: N | M41: A | N41: A | O41: A
B42: Passed/Failed | F42: P | G42: P | H42: P | I42: P | J42: P | K42: P | L42: P | M42: P | N42: P | O42: P
B43: Executed Date | F43: 46103 | G43: 46103 | H43: 46103 | I43: 46103 | J43: 46103 | K43: 46103 | L43: 46103 | M43: 46103 | N43: 46103 | O43: 46103
B44: Defect ID

Sheet getTotalMoney
A2: Function Code | C2: getTotalMoney | F2: Function Name | L2: getTotalMoney
A3: Created By | C3: Kien | F3: Executed By | L3: Kien
A4: Lines of code | C4: 8 | F4: Lack of test cases | L4: =IF(Functions!E6<>"N/A",SUM(C4*Functions!E6/1000,- O7),"N/A") -> -14.28
A5: Test requirement | C5: Used to calculate the total price of the shopping cart/product list.
A6: Passed | C6: Failed | F6: Untested | L6: N/A/B | O6: Total Test Cases
A7: =COUNTIF(F56:HQ57,"P") -> 10 | C7: =COUNTIF(F57:HQ57,"F") -> 0 | F7: =SUM(O7,- A7,- C7) -> 5 | L7: =COUNTIF(E55:HQ56,"N") -> 4 | M7: =COUNTIF(E55:HQ56,"A") -> 3 | N7: =COUNTIF(E55:HQ56,"B") -> 3 | O7: =COUNTA(E9:HT9) -> 15
F9: UTCID01 | G9: UTCID02 | H9: UTCID03 | I9: UTCID04 | J9: UTCID05 | K9: UTCID06 | L9: UTCID07 | M9: UTCID08 | N9: UTCID09 | O9: UTCID10 | P9: UTCID11 | Q9: UTCID12 | R9: UTCID13 | S9: UTCID14 | T9: UTCID15
A10: Condition | B10: Precondition | D10: app running
B12: quantity
D13: null | F13: O | L13: O
D14: -2 | K14: O
D15: 2 | G15: O | N15: O
D16: 2,3 | H16: O | O16: O
D17: 0 | I17: O
D18: 5 | J18: O
D19: 10 | M19: O
B21: price
D22: null | F22: O
D23: 0 | J23: O
D24: 10 | G24: O | I24: O | K24: O | L24: O
D25: 10.5 | H25: O | O25: O
D26: -1 | M26: O
D27: 20 | N27: O
A42: Confirm | B42: Return
D43: 0 | F43: O | I43: O | J43: O
D44: -20 | K44: O
D45: 20 | G45: O | N45: O
D46: 35 | H46: O
D47: 23 | O47: O
B50: Exception
B52: Log message
D53: Error | L53: O
A55: Result | B55: Type(N : Normal, A : Abnormal, B : Boundary) | F55: B | G55: N | H55: N | I55: B | J55: B | K55: A | L55: A | M55: A | N55: N | O55: N
B56: Passed/Failed | F56: P | G56: P | H56: P | I56: P | J56: P | K56: P | L56: P | M56: P | N56: P | O56: P
B57: Executed Date | F57: 46103 | G57: 46103 | H57: 46103 | I57: 46103 | J57: 46103 | K57: 46103 | L57: 46103 | M57: 46103 | N57: 46103 | O57: 46103
B58: Defect ID

Sheet getTotalPrice
A2: Function Code | C2: getTotalPrice() | F2: Function Name | L2: getTotalPrice()
A3: Created By | C3: Kien | F3: Executed By | L3: Kien
A4: Lines of code | C4: 8 | F4: Lack of test cases | L4: =IF(Functions!E6<>"N/A",SUM(C4*Functions!E6/1000,- O7),"N/A") -> -14.28
A5: Test requirement | C5: Used to calculate the total price for each product in the system.
A6: Passed | C6: Failed | F6: Untested | L6: N/A/B | O6: Total Test Cases
A7: =COUNTIF(F57:HQ58,"P") -> 10 | C7: =COUNTIF(F58:HQ58,"F") -> 0 | F7: =SUM(O7,- A7,- C7) -> 5 | L7: =COUNTIF(E56:HQ57,"N") -> 4 | M7: =COUNTIF(E56:HQ57,"A") -> 2 | N7: =COUNTIF(E56:HQ57,"B") -> 4 | O7: =COUNTA(E9:HT9) -> 15
F9: UTCID01 | G9: UTCID02 | H9: UTCID03 | I9: UTCID04 | J9: UTCID05 | K9: UTCID06 | L9: UTCID07 | M9: UTCID08 | N9: UTCID09 | O9: UTCID10 | P9: UTCID11 | Q9: UTCID12 | R9: UTCID13 | S9: UTCID14 | T9: UTCID15
A10: Condition | B10: Precondition | D10: app running
D12: Price
D13: 10 | F13: O | H13: O | N13: O
D14: 0 | G14: O
D15: 1000 | I15: O
D16: 10.5 | J16: O
D17: -10 | K17: O
D18: "abc" | L18: O
D19: 0.01 | M19: O
D20: "" | O20: O
D21: quantity
D22: -5
D23: 1 | M23: O
D24: 1.5 | N24: O
D25: 2 | F25: O | J25: O | K25: O | L25: O
D26: 5 | G26: O
D27: 0 | H27: O
D28: 2000 | I28: O
D29: "" | O29: O
A41: Confirm | B41: Return
D42: -20 | K42: O
D43: 0.01 | M43: O
D44: 15 | N44: O
D45: 20 | F45: O
D46: 0 | G46: O | H46: O
D47: 2000000 | I47: O
D48: 21 | J48: O
D49: ""
O50: O
B51: Exception
B53: Log message
D54: "error" | L54: O | O54: O
A56: Result | B56: Type(N : Normal, A : Abnormal, B : Boundary) | F56: N | G56: B | H56: B | I56: N | J56: N | K56: A | L56: B | M56: B | N56: N | O56: A
...

Sheet getTotalPrice(Order)
A2: Function Code | C2: getTotalPrice() | F2: Function Name | L2: getTotalPrice()
A3: Created By | C3: Kien | F3: Executed By | L3: Kien
A4: Lines of code | C4: 8 | F4: Lack of test cases | L4: =IF(Functions!E6<>"N/A",SUM(C4*Functions!E6/1000,- O7),"N/A") -> -14.28
A5: Test requirement | C5: Perform authentication and handle various input conditions.
A6: Passed | C6: Failed | F6: Untested | L6: N/A/B | O6: Total Test Cases
A7: =COUNTIF(F49:HQ49,"P") -> 9 | C7: =COUNTIF(F49:HQ49,"F") -> 0 | F7: =SUM(O7,- A7,- C7) -> 6 | L7: =COUNTIF(E48:HQ48,"N") -> 3 | M7: =COUNTIF(E48:HQ48,"A") -> 3 | N7: =COUNTIF(E48:HQ48,"B") -> 3 | O7: =COUNTA(E9:HT9) -> 15
F9: UTCID01 | G9: UTCID02 | H9: UTCID03 | I9: UTCID04 | J9: UTCID05 | K9: UTCID06 | L9: UTCID07 | M9: UTCID08 | N9: UTCID09 | O9: UTCID10 | P9: UTCID11 | Q9: UTCID12 | R9: UTCID13 | S9: UTCID14 | T9: UTCID15
A10: Condition | B10: Precondition | D10: app running
D12: Price
D13: 10 | F13: O | H13: O | L13: O
D14: 0 | G14: O
D15: 1000 | I15: O
D16: 10.5 | J16: O
D17: -10 | K17: O
D18: 0.01 | M18: O
D19: null | N19: O
D20: unitPrice
D21: 2 | F21: O
D22: 5 | G22: O
D23: 0 | H23: O
D24: 2000 | I24: O
D25: 2 | J25: O | K25: O | N25: O
D26: null | L26: O
D27: 0.005 | M27: O
A37: Confirm | B37: Return | D37: -20 | K37: O
D38: 20 | F38: O
D39: 0 | G39: O | H39: O
D40: 21 | J40: O
D41: 2000000 | I41: O
D42: 5 | M42: O
B43: Exception
B45: Log message
D46: Error | L46: O | N46: O
A48: Result | B48: Type(N : Normal, A : Abnormal, B : Boundary) | F48: N | G48: B | H48: B | I48: N | J48: N | K48: A | L48: A | M48: B | N48: A
B49: Passed/Failed | F49: P | G49: P | H49: P | I49: P | J49: P | K49: P | L49: P | M49: P | N49: P
B50: Executed Date | F50: 46103 | G50: 46103 | H50: 46103 | I50: 46103 | J50: 46103 | K50: 46103 | L50: 46103 | M50: 46103 | N50: 46103
B51: Defect ID

Sheet recalculateTotal
A2: Function Code | C2: recalculateTotal() | F2: Function Name | L2: recalculateTotal()
A3: Created By | C3: do nguyen hao | F3: Executed By | L3: do nguyen hao
A4: Lines of code | C4: 3 | F4: Lack of test cases | L4: =IF(Functions!E6<>"N/A",SUM(C4*Functions!E6/1000,- O7),"N/A") -> -14.73
A5: Test requirement | C5: The function calculate totalAmount as quantity × unitPrice
A6: Passed | C6: Failed | F6: Untested | L6: N/A/B | O6: Total Test Cases
A7: =COUNTIF(F44:HQ47,"P") -> 14 | C7: =COUNTIF(F44:HQ47,"F") -> 0 | F7: =SUM(O7,- A7,- C7) -> 1 | L7: =COUNTIF(E43:HQ46,"N") -> 5 | M7: =COUNTIF(E43:HQ46,"A") -> 5 | N7: =COUNTIF(E43:HQ46,"B") -> 4 | O7: =COUNTA(E9:HT9) -> 15
F9: UTCID01 | G9: UTCID02 | H9: UTCID03 | I9: UTCID04 | J9: UTCID05 | K9: UTCID06 | L9: UTCID07 | M9: UTCID08 | N9: UTCID09 | O9: UTCID10 | P9: UTCID11 | Q9: UTCID12 | R9: UTCID13 | S9: UTCID14 | T9: UTCID15
A10: Condition | B10: Precondition | D10: app runing
B12: quantity
D13: -1 | M13: O | O13: O | R13: O
D14: 0 | J14: O | L14: O
D15: 1 | F15: O | G15: O | Q15: O
D16: 10 | H16: O | I16: O | K16: O | N16: O
D17: 100 | P17: O | S17: O
B20: unitPrice
D21: -150
D22: -50 | N22: O | O22: O
D23: -5 | Q23: O
D24: 0 | K24: O | L24: O | S24: O
D25: 10 | F25: O | H25: O | R25: O
D26: 100 | G26: O | I26: O | J26: O | M26: O
D27: 150 | P27: O
A29: Confirm | B29: Return
D30: -500 | N30: O
D31: -100 | M31: O
D32: -10 | R32: O
D33: -5 | Q33: O
D34: 0 | J34: O | K34: O | L34: O | S34: O
D35: 10 | F35: O
D36: 50 | O36: O
D37: 100 | G37: O | H37: O
D38: 1000 | I38: O
D39: 15000 | P39: O
B41: Exception
B43: Log message
B46: Type(N : Normal, A : Abnormal, B : Boundary) | F46: N | G46: N | H46: N | I46: N | J46: B | K46: B | L46: B | M46: A | N46: A | O46: A | P46: N | Q46: A | R46: A | S46: B
B47: Passed/Failed | F47: P | G47: P | H47: P | I47: P | J47: P | K47: P | L47: P | M47: P | N47: P | O47: P | P47: P | Q47: P | R47: P | S47: P
A48: Result | B48: Executed Date | F48: 46104 | G48: 46104 | H48: 46104 | I48: 46104 | J48: 46104 | K48: 46104 | L48: 46104 | M48: 46104 | N48: 46104 | O48: 46104 | P48: 46104 | Q48: 46104 | R48: 46104 | S48: 46104
B49: Defect ID

Sheet updateQuantity
A2: Function Code | C2: updateQuantity | F2: Function Name | L2: updateQuantity
A3: Created By | C3: do nguyen hao | F3: Executed By | L3: do nguyen hao
A4: Lines of code | C4: 9 | F4: Lack of test cases | L4: =IF(Functions!E6<>"N/A",SUM(C4*Functions!E6/1000,- O7),"N/A") -> -14.19
A5: Test requirement | C5: Updates the quantity of an item in the cart
A6: Passed | C6: Failed | F6: Untested | L6: N/A/B | O6: Total Test Cases
A7: =COUNTIF(F35:HQ35,"P") -> 15 | C7: =COUNTIF(F32:HQ35,"F") -> 0 | F7: =SUM(O7,- A7,- C7) -> 0 | L7: =COUNTIF(E34:HQ34,"N") -> 6 | M7: =COUNTIF(E34:HQ34,"A") -> 5 | N7: =COUNTIF(E34:HQ34,"B") -> 4 | O7: =COUNTA(E9:HT9) -> 15
F9: UTCID01 | G9: UTCID02 | H9: UTCID03 | I9: UTCID04 | J9: UTCID05 | K9: UTCID06 | L9: UTCID07 | M9: UTCID08 | N9: UTCID09 | O9: UTCID10 | P9: UTCID11 | Q9: UTCID12 | R9: UTCID13 | S9: UTCID14 | T9: UTCID15
A10: Condition | B10: Precondition | D10: app runing
B12: item
D13: null | K13: O | L13: O | M13: O | R13: O
D14: not null | F14: O | G14: O | H14: O | I14: O | J14: O | N14: O | O14: O | P14: O | Q14: O | S14: O | T14: O
B16: unitPrice
D17: -5 | Q17: O
D18: -1 | J18: O | M18: O
D19: 0 | I19: O | L19: O | P19: O | T19: O
D20: 1 | F20: O | K20: O | N20: O
D21: 10 | G21: O | O21: O | R21: O
D22: 100 | H22: O | S22: O
A24: Confirm | B24: Return
D25: remove | I25: O | J25: O | P25: O | Q25: O | T25: O
D26: no change | K26: O | L26: O | M26: O | R26: O
D27: update | F27: O | G27: O | H27: O | N27: O | O27: O | S27: O
B29: Exception
B31: Log message
B34: Type(N : Normal, A : Abnormal, B : Boundary) | F34: N | G34: N | H34: N | I34: B | J34: A | K34: A | L34: B | M34: A | N34: N | O34: N | P34: B | Q34: A | R34: A | S34: N | T34: B
B35: Passed/Failed | F35: P | G35: P | H35: P | I35: P | J35: P | K35: P | L35: P | M35: P | N35: P | O35: P | P35: P | Q35: P | R35: P | S35: P | T35: P
A36: Result | B36: Executed Date | F36: 46107 | G36: 46107 | H36: 46107 | I36: 46107 | J36: 46107 | K36: 46107 | L36: 46107 | M36: 46107 | N36: 46107 | O36: 46107 | P36: 46107 | Q36: 46107 | R36: 46107 | S36: 46107 | T36: 46107
B37: Defect ID

Sheet getItemCount
A2: Function Code | C2: getItemCount | F2: Function Name | L2: getItemCount
A3: Created By | C3: do nguyen hao | F3: Executed By | L3: do nguyen hao
A4: Lines of code | C4: 8 | F4: Lack of test cases | L4: =IF(Functions!E6<>"N/A",SUM(C4*Functions!E6/1000,- O7),"N/A") -> -14.28
A5: Test requirement | C5: Calculates the total quantity of all items in the list
A6: Passed | C6: Failed | F6: Untested | L6: N/A/B | O6: Total Test Cases
A7: =COUNTIF(F29:HQ47,"P") -> 15 | C7: =COUNTIF(F22:HQ29,"F") -> 0 | F7: =SUM(O7,- A7,- C7) -> 0 | L7: =COUNTIF(E24:HQ46,"N") -> 5 | M7: =COUNTIF(E24:HQ46,"A") -> 7 | N7: =COUNTIF(E24:HQ46,"B") -> 3 | O7: =COUNTA(E9:HT9) -> 15
F9: UTCID01 | G9: UTCID02 | H9: UTCID03 | I9: UTCID04 | J9: UTCID05 | K9: UTCID06 | L9: UTCID07 | M9: UTCID08 | N9: UTCID09 | O9: UTCID10 | P9: UTCID11 | Q9: UTCID12 | R9: UTCID13 | S9: UTCID14 | T9: UTCID15
A10: Condition | B10: Precondition | D10: app runing
B12: item
D13: -10, -20 | F13: O
D14: -1 | G14: O
D15: 0 | H15: O
D16: 0, 0 | J16: O
D17: " " | K17: O
D18: -5, 0, 5 | I18: O
D19: 1, -1 | L19: O
D20: null | M20: O
D21: -1, 5 | N21: O
D22: 1, 2, 3 | O22: O
D23: 0, 10 | R23: O
D24: 5, 5, 5, 5 | P24: O
D25: 10, 20 | Q25: O
D26: 100 | S26: O
D27: 1000, 2000 | T27: O
A29: Confirm | B29: Return
D30: -30 | F30: O
D31: -1 | G31: O
D32: 0 | H32: O | I32: O | J32: O | K32: O | L32: O | M32: O
D33: 4 | N33: O
D34: 6 | O34: O
D35: 10 | R35: O
D36: 20 | P36: O
D37: 30 | Q37: O
D38: 100 | S38: O
D39: 3000 | T39: O
B41: Exception
B43: Log message
B46: Type(N : Normal, A : Abnormal, B : Boundary) | F46: A | G46: A | H46: B | I46: A | J46: B | K46: A | L46: A | M46: A | N46: A | O46: N | P46: N | Q46: N | R46: B | S46: N | T46: N
B47: Passed/Failed | F47: P | G47: P | H47: P | I47: P | J47: P | K47: P | L47: P | M47: P | N47: P | O47: P | P47: P | Q47: P | R47: P | S47: P | T47: P
A48: Result | B48: Executed Date | F48: 46107 | G48: 46107 | H48: 46107 | I48: 46107 | J48: 46107 | K48: 46107 | L48: 46107 | M48: 46107 | N48: 46107 | O48: 46107 | P48: 46107 | Q48: 46107 | R48: 46107 | S48: 46107 | T48: 46107
...
